Workbook
Name Choix1: '[1]Fiche rens. client Air Med '!$A$3
Name secoursgaz: [2]CONDITIONNE!$I:$I

Sheet Saisie
A1: FICHE CHANTIER – remplis uniquement la colonne B (cases jaunes)
A2: Champ | B2: Valeur | C2: Aide
A3: INFOS CLIENT
A4: Client | B4: Centre Hospitalier de PITHIVIERS
A5: Adresse | B5: 10 Bd Beauvallet
A6: Code postal | B6: 45300 | C6: CodePostalVille (Form 004) se fait tout seul
A7: Ville | B7: Pithiviers
A8: Contact client | B8: Mme Anaïs Minary
A9: Téléphone | B9: 03.85.81.83.61
A10: Mail | B10: anais.minary@ch-paray.fr
A11: N° ordre | B11: 84009436
A12: Chargé d’affaires | B12: Mr. Mhamed BENTANI
A14: SOURCES / CADRES
A15: Source 1 | B15: 1 Cadre CV18
A16: Source 2 | B16: 1 Cadre CV18
A17: Source 3 | B17: 1 X CV8
A18: Source rampe gauche (Form 004) | B18: 1 X CV18
A19: Source rampe secours (Form 004) | B19: 1 X CV8
A21: TYPOLOGIE – INSTALLATION FINALE (certificat tests alarmes + réception pharmaceutique)
A22: LIQ-LIQ-LIQ | C22: X = coché, vide = non coché
A23: LIQ-LIQ-GAZ | C23: X = coché, vide = non coché
A24: LIQ-GAZ-GAZ | C24: X = coché, vide = non coché
A25: GAZ-GAZ-GAZ | B25: X | C25: X = coché, vide = non coché
A26: MESS’AIR | C26: X = coché, vide = non coché
A27: MESS-VAC | C27: X = coché, vide = non coché
A28: Autre | C28: X = coché, vide = non coché
A29: Fluide | B29: Oxygène médicinal | C29: Choisir dans la liste (vide = case non cochée)
A31: TYPOLOGIE – INSTALLATION PROVISOIRE (certificat réception PROVISOIRE uniquement)
A32: LIQ-LIQ-LIQ | C32: X = coché, vide = non coché
A33: LIQ-LIQ-GAZ | C33: X = coché, vide = non coché
A34: LIQ-GAZ-GAZ | C34: X = coché, vide = non coché
A35: GAZ-GAZ-GAZ | C35: X = coché, vide = non coché
A36: MESS’AIR | C36: X = coché, vide = non coché
A37: MESS-VAC | C37: X = coché, vide = non coché
A38: Autre | C38: X = coché, vide = non coché
A39: Fluide | B39: Oxygène médicinal | C39: Choisir dans la liste (vide = case non cochée)
A41: DEMANDE EGYDE – SITE (onglet Demande EGYDE ; client, adresse, CP et ville = INFOS CLIENT)
A42: Date de la demande | B42: 46300 | C42: Format jj/mm/aaaa
A43: Date de M.E.S. souhaitée | B43: 46363 | C43: 3 jours ouvrés minimum si type existant
A44: Nom du site (création) | B44: CH DE PITHIVIERS / PITHIVIERS (45) | C44: Ex : CH DE PITHIVIERS / PITHIVIERS (45)
...

Sheet Fiches clients
A1: Client | B1: Adresse | C1: CodePostal | D1: Ville | E1: CodePostalVille | F1: Contact | G1: Telephone | H1: Email | I1: NumOrdre | J1: ChargeAffaires | K1: Source1 | L1: Source2 | M1: Source3 | N1: SourceRampeGauche | O1: SourceRampeSecours | P1: T_LIQLIQLIQ | Q1: T_LIQLIQGAZ | R1: T_LIQGAZGAZ | S1: T_GAZGAZGAZ | T1: T_MESSAIR | U1: T_MESSVAC | V1: T_AUTRE | W1: T_Fluide | X1: T_FLUIDEX | Y1: P_LIQLIQLIQ | Z1: P_LIQLIQGAZ | AA1: P_LIQGAZGAZ | AB1: P_GAZGAZGAZ | AC1: P_MESSAIR | AD1: P_MESSVAC | AE1: P_AUTRE | AF1: P_Fluide | AG1: P_FLUIDEX
A2: =Saisie!$B$4&"" | B2: =Saisie!$B$5&"" | C2: =Saisie!$B$6&"" | D2: =Saisie!$B$7&"" | E2: =TRIM(Saisie!$B$6&" "&Saisie!$B$7) | F2: =Saisie!$B$8&"" | G2: =Saisie!$B$9&"" | H2: =Saisie!$B$10&"" | I2: =Saisie!$B$11&"" | J2: =Saisie!$B$12&"" | K2: =Saisie!$B$15&"" | L2: =Saisie!$B$16&"" | M2: =Saisie!$B$17&"" | N2: =Saisie!$B$18&"" | O2: =Saisie!$B$19&"" | P2: =Saisie!$B$22&"" | Q2: =Saisie!$B$23&"" | R2: =Saisie!$B$24&"" | S2: =Saisie!$B$25&"" | T2: =Saisie!$B$26&"" | U2: =Saisie!$B$27&"" | V2: =Saisie!$B$28&"" | W2: =Saisie!$B$29&"" | X2: =IF(Saisie!$B$29="","","X") | Y2: =Saisie!$B$32&"" | Z2: =Saisie!$B$33&"" | AA2: =Saisie!$B$34&"" | AB2: =Saisie!$B$35&"" | AC2: =Saisie!$B$36&"" | AD2: =Saisie!$B$37&"" | AE2: =Saisie!$B$38&"" | AF2: =Saisie!$B$39&"" | AG2: =IF(Saisie!$B$39="","","X")

Sheet Demande EGYDE
A2: Nom du Site client : | B2: =IF(Saisie!$B$4="","",Saisie!$B$4) | F2: Date de la demande : | G2: =IF(Saisie!$B$42="","",Saisie!$B$42)
A3: Adresse | B3: =IF(Saisie!$B$5="","",Saisie!$B$5) | F3: Date de M.E.S. souhaitée : | G3: =IF(Saisie!$B$43="","",Saisie!$B$43)
F4: (3 jours ouvrés minimum si type existant)
A5: cp | B5: =IF(Saisie!$B$6="","",Saisie!$B$6)
A6: ville | B6: =IF(Saisie!$B$7="","",Saisie!$B$7)
A7: Création (à remplir seulement pour la demande d'intégation d'un nouveau Site)
A8: Nom du Site : | B8: =IF(Saisie!$B$44="","",Saisie!$B$44)
A9: Type de Site : | B9: =IF(Saisie!$B$45="","",Saisie!$B$45) | F9: SOURCE PRINCIPALE | G9: =IF(Saisie!$B$50="","",Saisie!$B$50)
A10: N° De Téléphone : | B10: =IF(Saisie!$B$46="","",Saisie!$B$46) | F10: SOURCE ATTENTE | G10: =IF(Saisie!$B$51="","",Saisie!$B$51)
A11: N° Identification : | B11: =IF(Saisie!$B$47="","",Saisie!$B$47) | F11: SOURCE SECOURS | G11: =IF(Saisie!$B$52="","",Saisie!$B$52)
A12: N° Esclave : | B12: =IF(Saisie!$B$48="","",Saisie!$B$48) | F12: Commercial responsable | G12: =IF(Saisie!$B$53="","",Saisie!$B$53)
A13: N° ASTREINTE | B13: =IF(Saisie!$B$49="","",Saisie!$B$49)
A15: Contact Client (à remplir à la création ou pour ajout nouvel utilisateur)
A16: Nom : | B16: =IF(Saisie!$B$56="","",Saisie!$B$56)
A17: Prénom : | B17: =IF(Saisie!$B$57="","",Saisie!$B$57)
A18: Adresse Mail : | B18: =IF(Saisie!$B$58="","",Saisie!$B$58)
A19: N° De Téléphone : | B19: =IF(Saisie!$B$59="","",Saisie!$B$59)
A20: Service : | B20: =IF(Saisie!$B$60="","",Saisie!$B$60)
A21: Identifiant : | B21: =IF(Saisie!$B$61="","",Saisie!$B$61)
A22: Mot de Passe : | B22: =IF(Saisie!$B$62="","",Saisie!$B$62)
A23: Type d'accès Client : | B23: =IF(Saisie!$B$63="","",Saisie!$B$63)
A24: ajout alarme | B24: =IF(Saisie!$B$64="","",Saisie!$B$64)
A26: Nom : | B26: =IF(Saisie!$B$67="","",Saisie!$B$67)
A27: Prénom : | B27: =IF(Saisie!$B$68="","",Saisie!$B$68)
A28: Adresse Mail : | B28: =IF(Saisie!$B$69="","",Saisie!$B$69)
A29: N° De Téléphone : | B29: =IF(Saisie!$B$70="","",Saisie!$B$70)
A30: Service : | B30: =IF(Saisie!$B$71="","",Saisie!$B$71)
A31: Identifiant : | B31: =IF(Saisie!$B$72="","",Saisie!$B$72)
A32: Mot de Passe : | B32: =IF(Saisie!$B$73="","",Saisie!$B$73)
A33: Type d'accès Client : | B33: =IF(Saisie!$B$74="","",Saisie!$B$74)
A34: ajout alarme | B34: =IF(Saisie!$B$75="","",Saisie!$B$75)
A36: Nom : | B36: =IF(Saisie!$B$78="","",Saisie!$B$78)
A37: Prénom : | B37: =IF(Saisie!$B$79="","",Saisie!$B$79)
A38: Adresse Mail : | B38: =IF(Saisie!$B$80="","",Saisie!$B$80)
A39: N° De Téléphone : | B39: =IF(Saisie!$B$81="","",Saisie!$B$81)
A40: Service : | B40: =IF(Saisie!$B$82="","",Saisie!$B$82)
A41: Identifiant : | B41: =IF(Saisie!$B$83="","",Saisie!$B$83)
A42: Mot de Passe : | B42: =IF(Saisie!$B$84="","",Saisie!$B$84)
A43: Type d'accès Client : | B43: =IF(Saisie!$B$85="","",Saisie!$B$85)
A44: ajout alarme | B44: =IF(Saisie!$B$86="","",Saisie!$B$86)

Sheet Lisez-moi
A1: Comment utiliser ce fichier
A2: 1. Onglet « Saisie » : c’est le SEUL onglet à remplir. Une ligne = un champ, tu tapes la valeur dans la colonne B (cases jaunes).
A3: 2. Typologie : mets X (liste déroulante) en face de la ou des cases à cocher, laisse vide sinon. Choisis le fluide dans la liste.
A4: 3. La section « PROVISOIRE » est indépendante : elle ne sert qu’au certificat de réception PROVISOIRE.
A5: La section « INSTALLATION FINALE » sert au certificat tests alarmes et au certificat de réception pharmaceutique.
A6: 4. Onglet « Fiches clients » : technique, se calcule tout seul. NE PAS MODIFIER. C’est lui que Word lit.
A7: 5. Enregistre et ferme Excel avant de lancer la fusion dans Word.
A8: 6. Demande EGYDE : remplis la section « DEMANDE EGYDE » en bas de Saisie, l’onglet « Demande EGYDE » se remplit tout seul (nom du site client, adresse, CP et ville repris des INFOS CLIENT). Imprime ou envoie cet onglet.
A10: Dans Word (à faire une fois par modèle)
A11: Publipostage > Sélection des destinataires > Utiliser une liste existante > ce fichier > onglet « Fiches clients$ ».
A12: Puis « Aperçu des résultats » pour vérifier, et « Terminer et fusionner » > « Modifier des documents individuels » > « Tous ».
A14: Nouveau chantier : écrase les valeurs de la colonne B de « Saisie », enregistre, puis refais la fusion.
... A53: Étapes 6 à 8 : Aperçu des résultats pour vérifier, puis Terminer & fusionner > Modifier des documents individuels > Tous > OK
